2019-06-08 01:02:07,134 INFO : Microblog startup [in F:\python\Flask\microblog\app\__init__.py:46]
2019-06-08 16:32:00,686 INFO : Microblog startup [in F:\python\Flask\microblog\app\__init__.py:46]
2019-06-08 16:32:41,843 INFO : Microblog startup [in F:\python\Flask\microblog\app\__init__.py:46]
2019-06-08 17:48:51,044 INFO : Microblog startup [in F:\python\Flask\microblog\app\__init__.py:46]
2019-06-09 00:25:26,241 INFO : Microblog startup [in F:\python\Flask\microblog\app\__init__.py:46]
2019-06-09 00:26:30,283 INFO : Microblog startup [in F:\python\Flask\microblog\app\__init__.py:46]
2019-06-09 00:32:52,636 INFO : Microblog startup [in F:\python\Flask\microblog\app\__init__.py:46]
2019-06-09 00:33:38,759 INFO : Microblog startup [in F:\python\Flask\microblog\app\__init__.py:46]
2019-06-09 00:36:46,202 INFO : Microblog startup [in F:\python\Flask\microblog\app\__init__.py:46]
2019-06-09 00:38:17,242 INFO : Microblog startup [in F:\python\Flask\microblog\app\__init__.py:46]
2019-06-09 00:38:53,947 INFO : Microblog startup [in F:\python\Flask\microblog\app\__init__.py:46]
2019-06-09 00:39:42,567 INFO : Microblog startup [in F:\python\Flask\microblog\app\__init__.py:46]
2019-06-09 00:46:23,839 INFO : Microblog startup [in F:\python\Flask\microblog\app\__init__.py:46]
2019-06-09 01:18:40,172 INFO : Microblog startup [in F:\python\Flask\microblog\app\__init__.py:46]
2019-06-09 01:19:29,446 ERROR : Exception on /user/abhay [GET] [in f:\python\flask\microblog\venv\lib\site-packages\flask\app.py:1780]
Traceback (most recent call last):
  File "f:\python\flask\microblog\venv\lib\site-packages\flask\app.py", line 2311, in wsgi_app
    response = self.full_dispatch_request()
  File "f:\python\flask\microblog\venv\lib\site-packages\flask\app.py", line 1834, in full_dispatch_request
    rv = self.handle_user_exception(e)
  File "f:\python\flask\microblog\venv\lib\site-packages\flask\app.py", line 1737, in handle_user_exception
    reraise(exc_type, exc_value, tb)
  File "f:\python\flask\microblog\venv\lib\site-packages\flask\_compat.py", line 36, in reraise
    raise value
  File "f:\python\flask\microblog\venv\lib\site-packages\flask\app.py", line 1832, in full_dispatch_request
    rv = self.dispatch_request()
  File "f:\python\flask\microblog\venv\lib\site-packages\flask\app.py", line 1818, in dispatch_request
    return self.view_functions[rule.endpoint](**req.view_args)
  File "f:\python\flask\microblog\venv\lib\site-packages\flask_login\utils.py", line 261, in decorated_view
    return func(*args, **kwargs)
  File "F:\python\Flask\microblog\app\routes.py", line 77, in user
    return render_template('user.html', user=user, posts=posts)
  File "f:\python\flask\microblog\venv\lib\site-packages\flask\templating.py", line 135, in render_template
    context, ctx.app)
  File "f:\python\flask\microblog\venv\lib\site-packages\flask\templating.py", line 117, in _render
    rv = template.render(context)
  File "f:\python\flask\microblog\venv\lib\site-packages\jinja2\asyncsupport.py", line 76, in render
    return original_render(self, *args, **kwargs)
  File "f:\python\flask\microblog\venv\lib\site-packages\jinja2\environment.py", line 1008, in render
    return self.environment.handle_exception(exc_info, True)
  File "f:\python\flask\microblog\venv\lib\site-packages\jinja2\environment.py", line 780, in handle_exception
    reraise(exc_type, exc_value, tb)
  File "f:\python\flask\microblog\venv\lib\site-packages\jinja2\_compat.py", line 37, in reraise
    raise value.with_traceback(tb)
  File "F:\python\Flask\microblog\app\templates\user.html", line 1, in top-level template code
    {% extends "base.html" %}
  File "F:\python\Flask\microblog\app\templates\base.html", line 33, in top-level template code
    {% block content %}{% endblock %}
  File "F:\python\Flask\microblog\app\templates\user.html", line 15, in block "content"
    {{user.follower.count() }} followers,
  File "f:\python\flask\microblog\venv\lib\site-packages\jinja2\environment.py", line 430, in getattr
    return getattr(obj, attribute)
jinja2.exceptions.UndefinedError: 'app.models.User object' has no attribute 'follower'
2019-06-09 01:20:26,962 ERROR : Exception on /user/abhayraj [GET] [in f:\python\flask\microblog\venv\lib\site-packages\flask\app.py:1780]
Traceback (most recent call last):
  File "f:\python\flask\microblog\venv\lib\site-packages\flask\app.py", line 2311, in wsgi_app
    response = self.full_dispatch_request()
  File "f:\python\flask\microblog\venv\lib\site-packages\flask\app.py", line 1834, in full_dispatch_request
    rv = self.handle_user_exception(e)
  File "f:\python\flask\microblog\venv\lib\site-packages\flask\app.py", line 1737, in handle_user_exception
    reraise(exc_type, exc_value, tb)
  File "f:\python\flask\microblog\venv\lib\site-packages\flask\_compat.py", line 36, in reraise
    raise value
  File "f:\python\flask\microblog\venv\lib\site-packages\flask\app.py", line 1832, in full_dispatch_request
    rv = self.dispatch_request()
  File "f:\python\flask\microblog\venv\lib\site-packages\flask\app.py", line 1818, in dispatch_request
    return self.view_functions[rule.endpoint](**req.view_args)
  File "f:\python\flask\microblog\venv\lib\site-packages\flask_login\utils.py", line 261, in decorated_view
    return func(*args, **kwargs)
  File "F:\python\Flask\microblog\app\routes.py", line 77, in user
    return render_template('user.html', user=user, posts=posts)
  File "f:\python\flask\microblog\venv\lib\site-packages\flask\templating.py", line 135, in render_template
    context, ctx.app)
  File "f:\python\flask\microblog\venv\lib\site-packages\flask\templating.py", line 117, in _render
    rv = template.render(context)
  File "f:\python\flask\microblog\venv\lib\site-packages\jinja2\asyncsupport.py", line 76, in render
    return original_render(self, *args, **kwargs)
  File "f:\python\flask\microblog\venv\lib\site-packages\jinja2\environment.py", line 1008, in render
    return self.environment.handle_exception(exc_info, True)
  File "f:\python\flask\microblog\venv\lib\site-packages\jinja2\environment.py", line 780, in handle_exception
    reraise(exc_type, exc_value, tb)
  File "f:\python\flask\microblog\venv\lib\site-packages\jinja2\_compat.py", line 37, in reraise
    raise value.with_traceback(tb)
  File "F:\python\Flask\microblog\app\templates\user.html", line 1, in top-level template code
    {% extends "base.html" %}
  File "F:\python\Flask\microblog\app\templates\base.html", line 33, in top-level template code
    {% block content %}{% endblock %}
  File "F:\python\Flask\microblog\app\templates\user.html", line 15, in block "content"
    {{user.follower.count() }} followers,
  File "f:\python\flask\microblog\venv\lib\site-packages\jinja2\environment.py", line 430, in getattr
    return getattr(obj, attribute)
jinja2.exceptions.UndefinedError: 'app.models.User object' has no attribute 'follower'
2019-06-09 01:20:33,728 ERROR : Exception on /user/abhayraj [GET] [in f:\python\flask\microblog\venv\lib\site-packages\flask\app.py:1780]
Traceback (most recent call last):
  File "f:\python\flask\microblog\venv\lib\site-packages\flask\app.py", line 2311, in wsgi_app
    response = self.full_dispatch_request()
  File "f:\python\flask\microblog\venv\lib\site-packages\flask\app.py", line 1834, in full_dispatch_request
    rv = self.handle_user_exception(e)
  File "f:\python\flask\microblog\venv\lib\site-packages\flask\app.py", line 1737, in handle_user_exception
    reraise(exc_type, exc_value, tb)
  File "f:\python\flask\microblog\venv\lib\site-packages\flask\_compat.py", line 36, in reraise
    raise value
  File "f:\python\flask\microblog\venv\lib\site-packages\flask\app.py", line 1832, in full_dispatch_request
    rv = self.dispatch_request()
  File "f:\python\flask\microblog\venv\lib\site-packages\flask\app.py", line 1818, in dispatch_request
    return self.view_functions[rule.endpoint](**req.view_args)
  File "f:\python\flask\microblog\venv\lib\site-packages\flask_login\utils.py", line 261, in decorated_view
    return func(*args, **kwargs)
  File "F:\python\Flask\microblog\app\routes.py", line 77, in user
    return render_template('user.html', user=user, posts=posts)
  File "f:\python\flask\microblog\venv\lib\site-packages\flask\templating.py", line 135, in render_template
    context, ctx.app)
  File "f:\python\flask\microblog\venv\lib\site-packages\flask\templating.py", line 117, in _render
    rv = template.render(context)
  File "f:\python\flask\microblog\venv\lib\site-packages\jinja2\asyncsupport.py", line 76, in render
    return original_render(self, *args, **kwargs)
  File "f:\python\flask\microblog\venv\lib\site-packages\jinja2\environment.py", line 1008, in render
    return self.environment.handle_exception(exc_info, True)
  File "f:\python\flask\microblog\venv\lib\site-packages\jinja2\environment.py", line 780, in handle_exception
    reraise(exc_type, exc_value, tb)
  File "f:\python\flask\microblog\venv\lib\site-packages\jinja2\_compat.py", line 37, in reraise
    raise value.with_traceback(tb)
  File "F:\python\Flask\microblog\app\templates\user.html", line 1, in top-level template code
    {% extends "base.html" %}
  File "F:\python\Flask\microblog\app\templates\base.html", line 33, in top-level template code
    {% block content %}{% endblock %}
  File "F:\python\Flask\microblog\app\templates\user.html", line 15, in block "content"
    {{user.follower.count() }} followers,
  File "f:\python\flask\microblog\venv\lib\site-packages\jinja2\environment.py", line 430, in getattr
    return getattr(obj, attribute)
jinja2.exceptions.UndefinedError: 'app.models.User object' has no attribute 'follower'
2019-06-09 01:22:00,419 INFO : Microblog startup [in F:\python\Flask\microblog\app\__init__.py:46]
2019-06-10 00:00:40,739 INFO : Microblog startup [in F:\python\Flask\microblog\app\__init__.py:46]
